<?xml version="1.0" ?>
<!-- =================================================================================== -->
<!-- |    This document was autogenerated by xacro from ar4.urdf.xacro                 | -->
<!-- |    EDITING THIS FILE BY HAND IS NOT RECOMMENDED                                 | -->
<!-- =================================================================================== -->
<robot name="ar4">
  <!-- ===================== Arm link xacro ================================== -->
  <!-- ===================== Box inertia xacro ==================================

  params:
  - m [float]: link mass;
  - x [float]: link dimension on the X-axis;
  - y [float]: link dimension on the Y-axis;
  - z [float]: link dimension on the Z-axis;
  - o_xyz [string]: position offset
  - o_rpy [string]: rotation offset
-->
  <link name="base_link">
    <origin rpy="0 0 0" xyz="0 0 0"/>
    <inertial>
      <mass value="0.7102"/>
      <inertia ixx="0.0007397916666666669" ixy="0.0" ixz="0.0" iyy="0.0035569183333333337" iyz="0.0" izz="0.004000793333333333"/>
      <origin rpy="0.0 0.0 0.0" xyz="-0.05 0.0 0.02"/>
    </inertial>
    <visual>
      <origin rpy="0.0                      0.0                      1.5708" xyz="0.0                      0.0                      0.0"/>
      <geometry>
        <mesh filename="../meshes/base_link.STL"/>
      </geometry>
      <material name="">
        <color rgba="1 1 0 1"/>
      </material>
    </visual>
    <collision>
      <origin rpy="0.0                      0.0                      1.5708" xyz="0.0                      0.0                      0.0"/>
      <geometry>
        <mesh filename="../meshes/base_link.STL"/>
      </geometry>
    </collision>
  </link>
  <link name="link_1">
    <origin rpy="0 0 0" xyz="0 0 0"/>
    <inertial>
      <mass value="0.88065"/>
      <inertia ixx="0.003669375000000001" ixy="0.0" ixz="0.0" iyy="0.003669375000000001" iyz="0.0" izz="0.0014677500000000005"/>
      <origin rpy="0.610865 0.418879 0.0" xyz="0.04 -0.01 0.1"/>
    </inertial>
    <visual>
      <origin rpy="3.1415                      0.0                      1.5708" xyz="0.0                      0.0                      0.0"/>
      <geometry>
        <mesh filename="../meshes/link_1.STL"/>
      </geometry>
      <material name="">
        <color rgba="1 1 0 1"/>
      </material>
    </visual>
    <collision>
      <origin rpy="3.1415                      0.0                      1.5708" xyz="0.0                      0.0                      0.0"/>
      <geometry>
        <mesh filename="../meshes/link_1.STL"/>
      </geometry>
    </collision>
  </link>
  <joint name="joint_1" type="revolute">
    <origin rpy="0 0 0" xyz="0 0 0"/>
    <parent link="base_link"/>
    <child link="link_1"/>
    <axis xyz="0 0 1"/>
    <limit effort="100" lower="-2.96705972839036" upper="2.96705972839036" velocity="0.5"/>
  </joint>
  <link name="link_2">
    <origin rpy="0 0 0" xyz="0 0 0"/>
    <inertial>
      <mass value="0.57738"/>
      <inertia ixx="0.0067168539999999995" ixy="0.0" ixz="0.0" iyy="0.0009623000000000001" iyz="0.0" izz="0.0067168539999999995"/>
      <origin rpy="0.0 0.0 0.0" xyz="0.0 -0.15 0.03"/>
    </inertial>
    <visual>
      <origin rpy="0.0                      3.1415                      0.0" xyz="0.0                      0.0                      0.0"/>
      <geometry>
        <mesh filename="../meshes/link_2.STL"/>
      </geometry>
      <material name="">
        <color rgba="1 1 0 1"/>
      </material>
    </visual>
    <collision>
      <origin rpy="0.0                      3.1415                      0.0" xyz="0.0                      0.0                      0.0"/>
      <geometry>
        <mesh filename="../meshes/link_2.STL"/>
      </geometry>
    </collision>
  </link>
  <joint name="joint_2" type="revolute">
    <origin rpy="-1.5708 0 0" xyz="0.0642 0 0.16977"/>
    <parent link="link_1"/>
    <child link="link_2"/>
    <axis xyz="0 0 1"/>
    <limit effort="100" lower="-0.7330382858376184" upper="1.5707963267948966" velocity="0.5"/>
  </joint>
  <link name="link_3">
    <origin rpy="0 0 0" xyz="0 0 0"/>
    <inertial>
      <mass value="0.1787"/>
      <inertia ixx="0.0002516691666666666" ixy="0.0" ixz="0.0" iyy="0.00018614583333333336" iyz="0.0" izz="0.00036335666666666665"/>
      <origin rpy="0.0 0.0 0.0" xyz="-0.01 0.0 0.0"/>
    </inertial>
    <visual>
      <origin rpy="3.1415                      0.0                      1.5708" xyz="0.0                      0.0                      0.0"/>
      <geometry>
        <mesh filename="../meshes/link_3.STL"/>
      </geometry>
      <material name="">
        <color rgba="1 1 0 1"/>
      </material>
    </visual>
    <collision>
      <origin rpy="3.1415                      0.0                      1.5708" xyz="0.0                      0.0                      0.0"/>
      <geometry>
        <mesh filename="../meshes/link_3.STL"/>
      </geometry>
    </collision>
  </link>
  <joint name="joint_3" type="revolute">
    <origin rpy="0 0 -1.5708" xyz="0 -0.305 0"/>
    <parent link="link_2"/>
    <child link="link_3"/>
    <axis xyz="0 0 1"/>
    <limit effort="100" lower="-1.5533430342749532" upper="0.9075712110370513" velocity="0.5"/>
  </joint>
  <link name="link_4">
    <origin rpy="0 0 0" xyz="0 0 0"/>
    <inertial>
      <mass value="0.34936"/>
      <inertia ixx="0.003086013333333334" ixy="0.0" ixz="0.0" iyy="0.003086013333333334" iyz="0.0" izz="0.000209616"/>
      <origin rpy="0.0 0.0 0.0" xyz="0.0 0.0 0.08"/>
    </inertial>
    <visual>
      <origin rpy="0.0                      3.1415                      0.0" xyz="0.0                      0.0                      0.0"/>
      <geometry>
        <mesh filename="../meshes/link_4.STL"/>
      </geometry>
      <material name="">
        <color rgba="1 1 0 1"/>
      </material>
    </visual>
    <collision>
      <origin rpy="0.0                      3.1415                      0.0" xyz="0.0                      0.0                      0.0"/>
      <geometry>
        <mesh filename="../meshes/link_4.STL"/>
      </geometry>
    </collision>
  </link>
  <joint name="joint_4" type="revolute">
    <origin rpy="-1.5708 0 0" xyz="0 0 0.0"/>
    <parent link="link_3"/>
    <child link="link_4"/>
    <axis xyz="0 0 1"/>
    <limit effort="100" lower="-2.8797932657906435" upper="2.8797932657906435" velocity="0.5"/>
  </joint>
  <link name="link_5">
    <origin rpy="0 0 0" xyz="0 0 0"/>
    <inertial>
      <mass value="0.11562"/>
      <inertia ixx="7.708e-05" ixy="0.0" ixz="0.0" iyy="0.000158014" iyz="0.0" izz="0.00011176600000000001"/>
      <origin rpy="0.0 0.0 0.0" xyz="0.0 0.0 0.0"/>
    </inertial>
    <visual>
      <origin rpy="0.0                      -1.5708                      0.0" xyz="0.0                      0.0                      0.0"/>
      <geometry>
        <mesh filename="../meshes/link_5.STL"/>
      </geometry>
      <material name="">
        <color rgba="1 1 0 1"/>
      </material>
    </visual>
    <collision>
      <origin rpy="0.0                      -1.5708                      0.0" xyz="0.0                      0.0                      0.0"/>
      <geometry>
        <mesh filename="../meshes/link_5.STL"/>
      </geometry>
    </collision>
  </link>
  <joint name="joint_5" type="revolute">
    <origin rpy="1.5708 0 0" xyz="0 0 0.22263"/>
    <parent link="link_4"/>
    <child link="link_5"/>
    <axis xyz="0 0 1"/>
    <limit effort="100" lower="-1.8325957145940461" upper="1.8325957145940461" velocity="1.0"/>
  </joint>
  <link name="link_6">
    <origin rpy="0 0 0" xyz="0 0 0"/>
    <inertial>
      <mass value="0.013863"/>
      <inertia ixx="9.242000000000001e-07" ixy="0.0" ixz="0.0" iyy="2.3105e-06" iyz="0.0" izz="2.3105e-06"/>
      <origin rpy="0.0 0.0 0.0" xyz="0.0 0.0 -0.01"/>
    </inertial>
    <visual>
      <origin rpy="0.0                      0.0                      0.0" xyz="0.0                      0.0                      0.0"/>
      <geometry>
        <mesh filename="../meshes/link_6.STL"/>
      </geometry>
      <material name="">
        <color rgba="1 1 0 1"/>
      </material>
    </visual>
    <collision>
      <origin rpy="0.0                      0.0                      0.0" xyz="0.0                      0.0                      0.0"/>
      <geometry>
        <mesh filename="../meshes/link_6.STL"/>
      </geometry>
    </collision>
  </link>
  <joint name="joint_6" type="revolute">
    <origin rpy="0 -1.5708 0" xyz="-0.03625 0 0"/>
    <parent link="link_5"/>
    <child link="link_6"/>
    <axis xyz="0 0 1"/>
    <limit effort="100" lower="-2.705260340591211" upper="2.705260340591211" velocity="1.0"/>
  </joint>
</robot>
